<?xml version="1.0"?>
<robot name="minicar_diff_real" xmlns:xacro="http://www.ros.org/wiki/xacro">

  <!-- Launch arguments -->
  <xacro:arg name="robot_ns" default="real_robot"/>

  <!-- Minimal robot structure for hardware interface -->
  <link name="base_link"/>
  <link name="left_front_wheel"/>
  <link name="right_front_wheel"/> 
  <link name="left_rear_wheel"/>
  <link name="right_rear_wheel"/>
  
  <joint name="left_front_wheel_joint" type="continuous">
    <parent link="base_link"/>
    <child link="left_front_wheel"/>
  </joint>
  <joint name="right_front_wheel_joint" type="continuous">
    <parent link="base_link"/>
    <child link="right_front_wheel"/>
  </joint>
  <joint name="left_rear_wheel_joint" type="continuous">
    <parent link="base_link"/>
    <child link="left_rear_wheel"/>
  </joint>
  <joint name="right_rear_wheel_joint" type="continuous">
    <parent link="base_link"/>
    <child link="right_rear_wheel"/>
  </joint>

  <!-- Real hardware interface (replace Gazebo plugin) -->
  <ros2_control name="RealSystem" type="system">
    <hardware>
      <plugin>minicar_diff_hardware/MinicarHardwareInterface</plugin>
      <param name="wheel_radius">0.035</param>
      <param name="encoder_ticks_per_revolution">1024</param>
      <param name="max_velocity_rad_per_sec">21.0</param>  <!-- 6V equivalent scaling for safe operation -->
      <param name="i2c_device">/dev/i2c-1</param>
      <param name="pca9685_address">64</param>
    </hardware>
    <!--
    <hardware>
      <plugin>mock_components/GenericSystem</plugin>
    </hardware>
    -->

    <joint name="left_front_wheel_joint">
      <command_interface name="velocity">
        <param name="min">-10.0</param>
        <param name="max">10.0</param>
      </command_interface>
      <state_interface name="velocity"/>
      <state_interface name="position"/>
    </joint>
    
    <joint name="right_front_wheel_joint">
      <command_interface name="velocity">
        <param name="min">-10.0</param>
        <param name="max">10.0</param>
      </command_interface>
      <state_interface name="velocity"/>
      <state_interface name="position"/>
    </joint>
    
    <joint name="left_rear_wheel_joint">
      <command_interface name="velocity">
        <param name="min">-10.0</param>
        <param name="max">10.0</param>
      </command_interface>
      <state_interface name="velocity"/>
      <state_interface name="position"/>
    </joint>
    
    <joint name="right_rear_wheel_joint">
      <command_interface name="velocity">
        <param name="min">-10.0</param>
        <param name="max">10.0</param>
      </command_interface>
      <state_interface name="velocity"/>
      <state_interface name="position"/>
    </joint>
  </ros2_control>

</robot>